<?xml version="1.0" encoding="utf-8"?>
<!-- =================================================================================== -->
<!-- |    This document was autogenerated by xacro from iiwa_agv.urdf.xacro            | -->
<!-- |    EDITING THIS FILE BY HAND IS NOT RECOMMENDED                                 | -->
<!-- =================================================================================== -->
<robot name="iiwa_agv">
  <transmission name="trans1">
    <type>transmission_interface/SimpleTransmission</type>
    <joint name="joint_a1">
      <hardwareInterface>hardware_interface/PositionJointInterface</hardwareInterface>
    </joint>
    <actuator name="motor1">
      <mechanicalReduction>1</mechanicalReduction>
    </actuator>
  </transmission>
  <transmission name="trans2">
    <type>transmission_interface/SimpleTransmission</type>
    <joint name="joint_a2">
      <hardwareInterface>hardware_interface/PositionJointInterface</hardwareInterface>
    </joint>
    <actuator name="motor2">
      <mechanicalReduction>1</mechanicalReduction>
    </actuator>
  </transmission>
  <transmission name="trans3">
    <type>transmission_interface/SimpleTransmission</type>
    <joint name="joint_a3">
      <hardwareInterface>hardware_interface/PositionJointInterface</hardwareInterface>
    </joint>
    <actuator name="motor3">
      <mechanicalReduction>1</mechanicalReduction>
    </actuator>
  </transmission>
  <transmission name="trans4">
    <type>transmission_interface/SimpleTransmission</type>
    <joint name="joint_a4">
      <hardwareInterface>hardware_interface/PositionJointInterface</hardwareInterface>
    </joint>
    <actuator name="motor4">
      <mechanicalReduction>1</mechanicalReduction>
    </actuator>
  </transmission>
  <transmission name="trans5">
    <type>transmission_interface/SimpleTransmission</type>
    <joint name="joint_a5">
      <hardwareInterface>hardware_interface/PositionJointInterface</hardwareInterface>
    </joint>
    <actuator name="motor5">
      <mechanicalReduction>1</mechanicalReduction>
    </actuator>
  </transmission>
  <transmission name="trans6">
    <type>transmission_interface/SimpleTransmission</type>
    <joint name="joint_a6">
      <hardwareInterface>hardware_interface/PositionJointInterface</hardwareInterface>
    </joint>
    <actuator name="motor6">
      <mechanicalReduction>1</mechanicalReduction>
    </actuator>
  </transmission>
  <transmission name="trans7">
    <type>transmission_interface/SimpleTransmission</type>
    <joint name="joint_a7">
      <hardwareInterface>hardware_interface/PositionJointInterface</hardwareInterface>
    </joint>
    <actuator name="motor7">
      <mechanicalReduction>1</mechanicalReduction>
    </actuator>
  </transmission>
  <gazebo reference="agv_link">
    <material>Gazebo/Blue</material>
    <mu1>0.5</mu1>
    <mu2>0.5</mu2>
  </gazebo>
  <gazebo reference="base_link">
    <material>Gazebo/Purple</material>
    <mu1>0.5</mu1>
    <mu2>0.5</mu2>
  </gazebo>
  <gazebo reference="link_1">
    <material>Gazebo/Yellow</material>
    <mu1>0.5</mu1>
    <mu2>0.5</mu2>
  </gazebo>
  <gazebo reference="link_2">
    <material>Gazebo/Red</material>
    <mu1>0.5</mu1>
    <mu2>0.5</mu2>
  </gazebo>
  <gazebo reference="link_3">
    <material>Gazebo/Orange</material>
    <mu1>0.5</mu1>
    <mu2>0.5</mu2>
  </gazebo>
  <gazebo reference="link_4">
    <material>Gazebo/Grey</material>
    <mu1>0.5</mu1>
    <mu2>0.5</mu2>
  </gazebo>
  <gazebo reference="link_5">
    <material>Gazebo/Green</material>
    <mu1>0.5</mu1>
    <mu2>0.5</mu2>
  </gazebo>
  <gazebo reference="link_6">
    <material>Gazebo/Blue</material>
    <mu1>0.5</mu1>
    <mu2>0.5</mu2>
  </gazebo>
  <gazebo reference="link_7">
    <material>Gazebo/Yellow</material>
    <mu1>0.5</mu1>
    <mu2>0.5</mu2>
  </gazebo>
  <gazebo reference="pan_link">
    <material>Gazebo/Black</material>
    <mu1>0.5</mu1>
    <mu2>0.5</mu2>
  </gazebo>
  <gazebo reference="xiao_arm1_link">
    <material>Gazebo/White</material>
    <mu1>0.5</mu1>
    <mu2>0.5</mu2>
  </gazebo>
  <gazebo reference="xiao_arm2_link">
    <material>Gazebo/Green</material>
    <mu1>0.5</mu1>
    <mu2>0.5</mu2>
  </gazebo>
  <gazebo reference="xiangji_link">
    <material>Gazebo/Orange</material>
    <mu1>0.5</mu1>
    <mu2>0.5</mu2>
  </gazebo>
  <!--ros control plugin-->
  <gazebo>
    <plugin filename="libgazebo_ros_control.so" name="gazebo_ros_control">
      <robotNamespace>/iiwa</robotNamespace>
      <robotParam>/iiwa/robot_description</robotParam>
      <robotSimType>gazebo_ros_control/DefaultRobotHWSim</robotSimType>
      <!--legacyModeNS>true</legacyModeNS-->
    </plugin>
  </gazebo>
  <!--move_base plugin -->
  <gazebo>
    <plugin filename="libgazebo_ros_planar_move.so" name="base_controller">
      <commandTopic>cmd_vel</commandTopic>
      <odometryTopic>world</odometryTopic>
      <odometryFrame>world</odometryFrame>
      <odometryRate>20.0</odometryRate>
      <robotBaseFrame>agv_link</robotBaseFrame>
    </plugin>
  </gazebo>
  <!-- link list -->
  <link name="agv_link">
    <inertial>
      <mass value="50.0"/>
      <inertia ixx="50.0" ixy="0.0" ixz="0.0" iyy="50.0" iyz="0.0" izz="50.0"/>
    </inertial>
    <visual>
      <origin rpy="1.570796 0 0" xyz="0 0 0"/>
      <geometry>
        <mesh filename="package://gazebo_example/meshes/che.STL"/>
      </geometry>
      <material name="blue"/>
    </visual>
    <collision>
      <origin rpy="1.570796 0 0" xyz="0 0 0"/>
      <geometry>
        <mesh filename="package://iiwa_agv/meshes/che.STL"/>
      </geometry>
    </collision>
  </link>
  <link name="base_link">
    <visual>
      <origin rpy="0 0 0" xyz="0 0 0"/>
      <geometry>
        <mesh filename="package://iiwa_agv/meshes/lbr_iiwa_14_r820/visual/base_link.dae"/>
      </geometry>
      <material name="purple"/>
    </visual>
    <collision>
      <origin rpy="0 0 0" xyz="0 0 0"/>
      <geometry>
        <mesh filename="package://iiwa_agv/meshes/lbr_iiwa_14_r820/collision/base_link.stl"/>
      </geometry>
    </collision>
    <inertial>
      <mass value="0.5"/>
      <origin rpy="0 0 0" xyz="0.0 0.0 0.0"/>
      <inertia ixx="0.00076329136135" ixy="0.0" ixz="0.0" iyy="0.00076329136135" iyz="0.0" izz="0.00140625"/>
    </inertial>
  </link>
  <link name="link_1">
    <visual>
      <origin rpy="0 0 0" xyz="0 0 0"/>
      <geometry>
        <mesh filename="package://iiwa_agv/meshes/lbr_iiwa_14_r820/visual/link_1.dae"/>
      </geometry>
      <material name="yellow"/>
    </visual>
    <collision>
      <origin rpy="0 0 0" xyz="0 0 0"/>
      <geometry>
        <mesh filename="package://iiwa_agv/meshes/lbr_iiwa_14_r820/collision/link_1.stl"/>
      </geometry>
    </collision>
    <inertial>
      <mass value="0.5"/>
      <origin rpy="0 0 0" xyz="0.0 0.0 0.0"/>
      <inertia ixx="0.00076329136135" ixy="0.0" ixz="0.0" iyy="0.00076329136135" iyz="0.0" izz="0.00140625"/>
    </inertial>
  </link>
  <link name="link_2">
    <visual>
      <origin rpy="0 0 0" xyz="0 0 0"/>
      <geometry>
        <mesh filename="package://iiwa_agv/meshes/lbr_iiwa_14_r820/visual/link_2.dae"/>
      </geometry>
      <material name="red"/>
    </visual>
    <collision>
      <origin rpy="0 0 0" xyz="0 0 0"/>
      <geometry>
        <mesh filename="package://iiwa_agv/meshes/lbr_iiwa_14_r820/collision/link_2.stl"/>
      </geometry>
    </collision>
    <inertial>
      <mass value="0.5"/>
      <origin rpy="0 0 0" xyz="0.0 0.0 0.0"/>
      <inertia ixx="0.00076329136135" ixy="0.0" ixz="0.0" iyy="0.00076329136135" iyz="0.0" izz="0.00140625"/>
    </inertial>
  </link>
  <link name="link_3">
    <visual>
      <origin rpy="0 0 0" xyz="0 0 0"/>
      <geometry>
        <mesh filename="package://iiwa_agv/meshes/lbr_iiwa_14_r820/visual/link_3.dae"/>
      </geometry>
      <material name="orange"/>
    </visual>
    <collision>
      <origin rpy="0 0 0" xyz="0 0 0"/>
      <geometry>
        <mesh filename="package://iiwa_agv/meshes/lbr_iiwa_14_r820/collision/link_3.stl"/>
      </geometry>
    </collision>
    <inertial>
      <mass value="0.5"/>
      <origin rpy="0 0 0" xyz="0.0 0.0 0.0"/>
      <inertia ixx="0.00076329136135" ixy="0.0" ixz="0.0" iyy="0.00076329136135" iyz="0.0" izz="0.00140625"/>
    </inertial>
  </link>
  <link name="link_4">
    <visual>
      <origin rpy="0 0 0" xyz="0 0 0"/>
      <geometry>
        <mesh filename="package://iiwa_agv/meshes/lbr_iiwa_14_r820/visual/link_4.dae"/>
      </geometry>
      <material name="grey"/>
    </visual>
    <collision>
      <origin rpy="0 0 0" xyz="0 0 0"/>
      <geometry>
        <mesh filename="package://iiwa_agv/meshes/lbr_iiwa_14_r820/collision/link_4.stl"/>
      </geometry>
    </collision>
    <inertial>
      <mass value="0.5"/>
      <origin rpy="0 0 0" xyz="0.0 0.0 0.0"/>
      <inertia ixx="0.00076329136135" ixy="0.0" ixz="0.0" iyy="0.00076329136135" iyz="0.0" izz="0.00140625"/>
    </inertial>
  </link>
  <link name="link_5">
    <visual>
      <origin rpy="0 0 0" xyz="0 0 0"/>
      <geometry>
        <mesh filename="package://iiwa_agv/meshes/lbr_iiwa_14_r820/visual/link_5.dae"/>
      </geometry>
      <material name="green"/>
    </visual>
    <collision>
      <origin rpy="0 0 0" xyz="0 0 0"/>
      <geometry>
        <mesh filename="package://iiwa_agv/meshes/lbr_iiwa_14_r820/collision/link_5.stl"/>
      </geometry>
    </collision>
    <inertial>
      <mass value="0.5"/>
      <origin rpy="0 0 0" xyz="0.0 0.0 0.0"/>
      <inertia ixx="0.00076329136135" ixy="0.0" ixz="0.0" iyy="0.00076329136135" iyz="0.0" izz="0.00140625"/>
    </inertial>
  </link>
  <link name="link_6">
    <visual>
      <origin rpy="0 0 0" xyz="0 0 0"/>
      <geometry>
        <mesh filename="package://iiwa_agv/meshes/lbr_iiwa_14_r820/visual/link_6.dae"/>
      </geometry>
      <material name="blue"/>
    </visual>
    <collision>
      <origin rpy="0 0 0" xyz="0 0 0"/>
      <geometry>
        <mesh filename="package://iiwa_agv/meshes/lbr_iiwa_14_r820/collision/link_6.stl"/>
      </geometry>
    </collision>
    <inertial>
      <mass value="0.5"/>
      <origin rpy="0 0 0" xyz="0.0 0.0 0.0"/>
      <inertia ixx="0.00076329136135" ixy="0.0" ixz="0.0" iyy="0.00076329136135" iyz="0.0" izz="0.00140625"/>
    </inertial>
  </link>
  <link name="link_7">
    <visual>
      <origin rpy="0 0 0" xyz="0 0 0"/>
      <geometry>
        <mesh filename="package://iiwa_agv/meshes/lbr_iiwa_14_r820/visual/link_7.dae"/>
      </geometry>
      <material name="yellow"/>
    </visual>
    <collision>
      <origin rpy="0 0 0" xyz="0 0 0"/>
      <geometry>
        <mesh filename="package://iiwa_agv/meshes/lbr_iiwa_14_r820/collision/link_7.stl"/>
      </geometry>
    </collision>
    <inertial>
      <mass value="0.5"/>
      <origin rpy="0 0 0" xyz="0.0 0.0 0.0"/>
      <inertia ixx="0.00076329136135" ixy="0.0" ixz="0.0" iyy="0.00076329136135" iyz="0.0" izz="0.00140625"/>
    </inertial>
  </link>
  <link name="tool0"/>
  <link name="pan_link">
    <visual>
      <geometry>
        <mesh filename="package://iiwa_agv/meshes/pan.STL"/>
      </geometry>
      <material name="black"/>
    </visual>
    <collision>
      <geometry>
        <mesh filename="package://iiwa_agv/meshes/pan.STL"/>
      </geometry>
    </collision>
    <inertial>
      <mass value="0.01"/>
      <origin rpy="0 0 0" xyz="0.0 0.0 0.0"/>
      <inertia ixx="6.3333308e-06" ixy="0.0" ixz="0.0" iyy="6.3333308e-06" iyz="0.0" izz="1.25e-05"/>
    </inertial>
  </link>
  <link name="xiao_arm1_link">
    <visual>
      <geometry>
        <mesh filename="package://iiwa_agv/meshes/xiao_arm.STL"/>
      </geometry>
      <material name="white"/>
    </visual>
    <collision>
      <geometry>
        <mesh filename="package://iiwa_agv/meshes/xiao_arm.STL"/>
      </geometry>
    </collision>
    <inertial>
      <mass value="0.01"/>
      <origin rpy="0 0 0" xyz="0.0 0.0 0.0"/>
      <inertia ixx="6.3333308e-06" ixy="0.0" ixz="0.0" iyy="6.3333308e-06" iyz="0.0" izz="1.25e-05"/>
    </inertial>
  </link>
  <link name="xiao_arm2_link">
    <visual>
      <geometry>
        <mesh filename="package://iiwa_agv/meshes/xiao_arm.STL"/>
      </geometry>
      <material name="green"/>
    </visual>
    <collision>
      <geometry>
        <mesh filename="package://iiwa_agv/meshes/xiao_arm.STL"/>
      </geometry>
    </collision>
    <inertial>
      <mass value="0.01"/>
      <origin rpy="0 0 0" xyz="0.0 0.0 0.0"/>
      <inertia ixx="6.3333308e-06" ixy="0.0" ixz="0.0" iyy="6.3333308e-06" iyz="0.0" izz="1.25e-05"/>
    </inertial>
  </link>
  <link name="xiangji_link">
    <visual>
      <geometry>
        <mesh filename="package://iiwa_agv/meshes/xiangji.STL"/>
      </geometry>
      <material name="orange"/>
    </visual>
    <collision>
      <geometry>
        <mesh filename="package://iiwa_agv/meshes/xiao_arm.STL"/>
      </geometry>
    </collision>
    <inertial>
      <mass value="0.01"/>
      <origin rpy="0 0 0" xyz="0.0 0.0 0.0"/>
      <inertia ixx="6.3333308e-06" ixy="0.0" ixz="0.0" iyy="6.3333308e-06" iyz="0.0" izz="1.25e-05"/>
    </inertial>
  </link>
  <!-- end of link list -->
  <!-- joint list -->
  <joint name="agv_to_base_joint" type="fixed">
    <origin rpy="0 0 0" xyz="0 0 0.23"/>
    <parent link="agv_link"/>
    <child link="base_link"/>
  </joint>
  <joint name="joint_a1" type="revolute">
    <origin rpy="0 0 0" xyz="0 0 0"/>
    <parent link="base_link"/>
    <child link="link_1"/>
    <axis xyz="0 0 1"/>
    <limit effort="50" lower="-2.9668" upper="2.9668" velocity="1.4834"/>
  </joint>
  <joint name="joint_a2" type="revolute">
    <origin rpy="0 0 0" xyz="-0.00043624 0 0.36"/>
    <parent link="link_1"/>
    <child link="link_2"/>
    <axis xyz="0 1 0"/>
    <limit effort="50" lower="-2.0942" upper="2.0942" velocity="1.4834"/>
  </joint>
  <joint name="joint_a3" type="revolute">
    <origin rpy="0 0 0" xyz="0 0 0"/>
    <parent link="link_2"/>
    <child link="link_3"/>
    <axis xyz="0 0 1"/>
    <limit effort="50" lower="-2.9668" upper="2.9668" velocity="1.7452"/>
  </joint>
  <joint name="joint_a4" type="revolute">
    <origin rpy="0 0 0" xyz="0.00043624 0 0.42"/>
    <parent link="link_3"/>
    <child link="link_4"/>
    <axis xyz="0 -1 0"/>
    <limit effort="50" lower="-2.0942" upper="2.0942" velocity="1.3089"/>
  </joint>
  <joint name="joint_a5" type="revolute">
    <origin rpy="0 0 0" xyz="0 0 0"/>
    <parent link="link_4"/>
    <child link="link_5"/>
    <axis xyz="0 0 1"/>
    <limit effort="50" lower="-2.9668" upper="2.9668" velocity="2.2688"/>
  </joint>
  <joint name="joint_a6" type="revolute">
    <origin rpy="0 0 0" xyz="0 0 0.4"/>
    <parent link="link_5"/>
    <child link="link_6"/>
    <axis xyz="0 1 0"/>
    <limit effort="50" lower="-2.0942" upper="2.0942" velocity="2.356"/>
  </joint>
  <joint name="joint_a7" type="revolute">
    <origin rpy="0 0 0" xyz="0 0 0"/>
    <parent link="link_6"/>
    <child link="link_7"/>
    <axis xyz="0 0 1"/>
    <limit effort="50" lower="-3.0541" upper="3.0541" velocity="2.356"/>
  </joint>
  <joint name="joint_a7-tool0" type="fixed">
    <origin rpy="0 0 0" xyz="0 0 0.126"/>
    <parent link="link_7"/>
    <child link="tool0"/>
    <axis xyz="0 0 0"/>
  </joint>
  <joint name="link7_to_pan_joint" type="fixed">
    <parent link="link_7"/>
    <child link="pan_link"/>
    <origin rpy="1.5708 0.0 0.0" xyz="0.0 0.0 0.12"/>
    <axis xyz="0 1 0"/>
    <dynamics damping="0.0" friction="0.0"/>
  </joint>
  <joint name="pan_to_xiao_arm1_joint" type="fixed">
    <parent link="pan_link"/>
    <child link="xiao_arm1_link"/>
    <origin rpy="0.0 0.0 0.0" xyz="0.0 0.0 -0.47"/>
    <axis xyz="0 1 0"/>
    <dynamics damping="0.0" friction="0.0"/>
  </joint>
  <joint name="pan_to_xiao_arm2_joint" type="fixed">
    <parent link="pan_link"/>
    <child link="xiao_arm2_link"/>
    <origin rpy="0.0 0.0 0.0" xyz="-0.15 0.0 -0.47"/>
    <axis xyz="0 1 0"/>
    <dynamics damping="0.0" friction="0.0"/>
  </joint>
  <joint name="pan_to_xiangji_joint" type="fixed">
    <parent link="pan_link"/>
    <child link="xiangji_link"/>
    <origin rpy="-1.570796 0.0 0.0" xyz="0.0 0.065 -0.1"/>
    <axis xyz="0 1 0"/>
    <dynamics damping="0.0" friction="0.0"/>
  </joint>
  <!-- end of joint list -->
</robot>
